Workbook

Sheet IT Summary
A1: IT Summary March 2026
D3: 5 Year Contract Spend | E3: Total Spend FY 2025/2026 | F3: Total Spend FY 2024/2025 | G3: Total Spend FY 2023/2024
D4: Feb 24- Mar 26 | E4: Aug 25-Mar 26 | F4: Aug 24 - Jul 25 | G4: Feb 24 - Jul 24
A5: Filter Application Cost Breakdown | B5: Area | C5: Notes | D5: Total | E5: FY2025/26 | F5: FY 2024/25 | G5: FY 2023/24
C6: OVERALL TOTAL COSTS | D6: =SUM(D17,D39,D45) -> 11120524 | E6: =SUM(E17,E39,E45) -> 3772570.8 | F6: =SUM(F17,F39,F45) -> 5119939.1 | G6: =SUM(G17,G39,G45) -> 2228013.8 | H6: =SUM(E6,F6+G6)-D6 -> 0
A8: FILTER INTERNAL COSTS | D8: Feb 24- Mar 26 | E8: Aug 25 -Mar 26 | F8: Aug 24 - Jul 25 | G8: Feb 23 - Jul 24
A9: Programme Costs | B9: Research & Planning | C9: Includes industry research, feasibility and strategic design activities, programme management, financial management, strategic and senior meetings & reporting. | D9: =Summary!AX156 -> 707917.52 | E9: =Summary!AM156 -> 148664.79 | F9: =Summary!U156 -> 339774.37 | G9: =Summary!J156 -> 219478.36
A10: Team Management Costs | B10: Employee Related Costs | C10: Any activity relating to detailed planning, design, development, test and release of the JDW applications or changes to applications relating to People. | D10: =Summary!AX157 -> 2073989.8 | E10: =Summary!AM157 -> 744679.93 | F10: =Summary!U157 -> 954778.66 | G10: =Summary!J157 -> 374531.2
A11: Development & Delivery Costs | B11: People | C11: Any activity relating to detailed planning, design, development, test and release of the JDW applications or changes to applications relating to People. | D11: =Summary!AX158 -> 2338552.3 | E11: =Summary!AM158 -> 807986.84 | F11: =Summary!U158 -> 1078674.5 | G11: =Summary!J158 -> 451890.93
B12: Customer | C12: Any activity relating to detailed planning, design, development, test and release of the JDW applications or changes to applications relating to Customers. | D12: =Summary!AX159 -> 2582526.6 | E12: =Summary!AM159 -> 830931.13 | F12: =Summary!U159 -> 1067208.7 | G12: =Summary!J159 -> 684386.85
B13: Business & Financial Controls | C13: Any activity relating to detailed planning, design, development, test and release of the JDW applications or changes to applications which support pub or head office process or controls (e.g. Authentication, myCompliance). | D13: =Summary!AX160 -> 387667.97 | E13: =Summary!AM160 -> 89186.58 | F13: =Summary!U160 -> 240568.58 | G13: =Summary!J160 -> 57912.801
B14: Franchising | C14: Any activity relating to detailed planning, design, development, test and release of Franchise applications or changes to applications relating to Franchising. | D14: =Summary!AX161 -> 535319 | E14: =Summary!AM161 -> 265878.82 | F14: =Summary!U161 -> 249260.05 | G14: =Summary!J161 -> 20180.138
B15: Technology & Security | C15: Includes any activity relating to the introduction or improvement of common technical platforms (such as AI and Automation) or technical compliance (such as Security, DR and PCI). | D15: =Summary!AX164 -> 27709.062 | E15: =Summary!AM164 -> 11994.456 | F15: =Summary!U164 -> 14264.519 | G15: =Summary!J164 -> 1450.0867
A16: Support & Maintenance Costs | B16: All | C16: Set monthly charge for ongoing support and maintenance of the applications and services provided. | D16: =Summary!AX165 -> 349371.69 | E16: =Summary!AM165 -> 165565.46 | F16: =Summary!U165 -> 145226.6 | G16: =Summary!J165 -> 38579.626
C17: TOTAL | D17: =SUM(D9:D16) -> 9003054 | E17: =SUM(E9:E16) -> 3064888 | F17: =SUM(F9:F16) -> 4089756 | G17: =SUM(G9:G16) -> 1848410 | H17: =SUM(E17:G17)-D17 -> 0
A19: FILTER MANAGED 3rd PARTY SERVICES | D19: Feb 24 - Mar 26 | E19: Aug 25 - Mar 26 | F19: Aug 24 - Jul 25 | G19: Feb 24 - Jul 24
A20: 3rd Party Costs (variable) | B20: Apple | C20: myJDW - Developer Enterprise Program - Allows large organisations to develop and deploy proprietary, internal-use apps to their employees. | D20: =SUM(E20,F20,G20) -> 767 | E20: 249 | F20: 259 | G20: 259 | I20: Will be charged March 2026
B21: AWS | C21: Management Account - test and UAT AWS accounts. From June 2025, a gradual shift was started to move test and UAT environments to a separate Filter AWS environment, starting with Order & Pay App and progressing to People Apps. This is expected to run at c.£5,000 per month, and the JDW AWS account will adjust down accordingly. | D21: =SUM(E21,F21,G21) -> 27470.2 | E21: ='Aug 25'!G88+'Sep 25'!G88+'Oct 25'!G88+'Nov 25'!G88+'Dec 25'!G88+'Jan - 26'!G88+'Feb - 26'!G88+'Mar - 26'!G88 -> 26105.2 | F21: =596+769 -> 1365 | I21: Charged monthly dependent on usage
B22: AWS | C22: Select Tier Partnership. Annual charge. | D22: =SUM(E22,F22,G22) -> 2122.04 | E22: ='Nov 25'!G89 -> 1136.04 | F22: 986 | I22: Charged November 2025
B23: CookieYes | C23: Corporate, Hotels, Investors, Franchising Websites - Cookie Consent Solution | D23: =SUM(E23,F23,G23) -> 1302 | E23: ='Oct 25'!G90 -> 462 | F23: 420 | G23: 420
B24: CookieYes | C24: Careers Website - Cookie Consent Solution | D24: =SUM(E24,F24,G24) -> 1302 | E24: ='Oct 25'!G91 -> 462 | F24: 420 | G24: 420
B25: Cosmic Giant | C25: Gravity Forms Enhancement Plugin - myJDW, Corporate, Hotels, Careers, Investors, Franchising | D25: =SUM(E25,F25,G25) -> 791.69 | E25: ='Jan - 26'!F92 -> 263.69 | F25: 264 | G25: 264
B26: Elastic Search | C26: myJDW, mySchedule - Open source search and analytics engine. Charge, dependent on usage. | D26: =SUM(E26,F26,G26) -> 1914.78 | E26: ='Aug 25'!G93+'Sep 25'!G93+'Oct 25'!G93+'Nov 25'!G93+'Dec 25'!G93+'Jan - 26'!G93+'Feb - 26'!G93+'Mar - 26'!G93 -> 474.78 | F26: 720 | G26: 720 | I26: Charged monthly dependent on usage
B27: Flagsmith | C27: myJDW, mySchedule, Order & Pay - Open-source feature flag service to toggle features on and off. Annual charge - new 3 year commitment March 2025 to March 2028. Next charge March 2026. | D27: =SUM(E27,F27,G27) -> 104386.67 | E27: ='Mar - 26'!F94 -> 36951.55 | F27: 31976.33 | G27: 35458.79 | I27: Will be charged March 2026
B28: GitHub Advanced Security | C28: Github integrates deeply into our development and deployment workflow, scanning code at multiple points. £35K per year (overs 35 developers, QAs, dev ops engineers and support). Billed ~£3K per month through Filter. There will be some fluctuation due to exchange rates and use of CI/CD deployment. | D28: =SUM(E28,F28,G28) -> 2296.86 | E28: =SUM('Feb - 26'!G95,'Mar - 26'!G95) -> 2296.86 | I28: Commencing Febraury 2026
B29: Google Maps | C29: Corporate , Hotels Websites - For map API usage. Monthly charge, variable based on usage. | D29: =SUM(E29,F29,G29) -> 197998.39 | E29: ='Aug 25'!G95+'Sep 25'!G95+'Oct 25'!G95+'Nov 25'!G95+'Dec 25'!G96+'Jan - 26'!G96+'Feb - 26'!G96+'Mar - 26'!G96 -> 19438.29 | F29: =SUM(126221.29+'May 25'!G94+'June 25'!G95+'July 25'!G95) -> 138560.1 | G29: 40000 | I29: Charged monthly dependent on usage
B30: Google PPC Pilot | C30: Paid Adverts "Google Pay Per Click" Media Fee for November and December. | D30: =SUM(E30,F30,G30) -> 2595.96 | E30: ='Dec 25'!G97 -> 2595.96
B31: Ionic | C31: Order & Pay App - Cross platform application framework. Enterprise package, live updates and payments modules. Charged for two year commitment. Renewed in March. Slight annual increase due to increase in live updates by further 10 million. | D31: =SUM(E31,F31,G31) -> 147410.4 | F31: 105274.4 | G31: 42136 | I31: Will be charged March 2026
B32: Ionic | C32: Order & Pay App - Cross platform application framework. Auth Connect and Identity Vault modules to be used with Customer Accounts. Charged for 21 month commitment. | D32: =SUM(E32,F32,G32) -> 54268.4 | F32: 54268.4 | G32: 0 | I32: Will be charged June 2026
B33: MonSpark | C33: Order & Pay App, Hotels - Source code monitoring for PCI-DSS. Annual charge. | D33: =SUM(E33,F33,G33) -> 1367.84 | E33: ='Mar - 26'!F103 -> 683.84 | F33: 684 | G33: 0 | I33: Will be charged March 2026
B34: Open Weather | C34: mySchedule - Open Weather History Bulk (3 Years). One-off charge for historical capture of data. | D34: =SUM(E34,F34,G34) -> 6160 | E34: ='Dec 25'!G104 -> 6160 | F34: 0 | G34: 0
B35: Open Weather | C35: mySchedule - Open Weather Forecast Subscription & Actual History Prior Day. Fluctuates depending on usage, charged each month. | D35: =SUM(E35,F35,G35) -> 2745.6 | E35: ='Dec 25'!G105+'Jan - 26'!G105+'Feb - 26'!G105+'Mar - 26'!G105 -> 2745.6
B36: Report URL | C36: myJDW, Corporate, Hotels, Careers, Investors, Franchising, Careers - Content-Security-Policy-Report-Only, web application to restrict sources for JavaScript (and other resources, such as images or CSS). | D36: =SUM(E36,F36,G36) -> 1230 | E36: ='Oct 25'!G103+'Nov 25'!G103+'Dec 25'!G106+'Jan - 26'!G106+'Feb - 26'!G106+'Mar - 26'!G106 -> 1230
B37: WordPress Plugins | C37: myJDW, Corporate, Hotels, Careers, Investors, Franchising, Careers - To enhance Website functionality. Advanced Custom Fields PRO, Admin Columns Pro, Gravity Forms, Imagify, SearchWP, WP All Import Pro, WP Rocket, PersonalizeWP, WPMail SMTP Pro. Annual charge. | D37: =SUM(E37,F37,G37) -> 3750 | E37: ='Mar - 26'!F108 -> 1250 | F37: 1250 | G37: 1250
B38: Yoast SEO Premium | C38: Corporate, Hotels, Careers, Investors, Franchising - a paid version of the Yoast SEO plugin that provides advanced features to improve a website's search engine optimisation. | D38: =SUM(E38,F38,G38) -> 906 | E38: ='Jan - 26'!F110 -> 302 | F38: 302 | G38: 302
C39: TOTAL | D39: =SUM(D20:D38) -> 560785.83 | E39: =SUM(E20:E38) -> 102806.81 | F39: =SUM(F20:F38) -> 336749.23 | G39: =SUM(G20:G38) -> 121229.79 | H39: =SUM(E39:G39)-D39 -> 0
A41: JDW MANAGED 3rd PARTY SERVICES | D41: Feb 24 - Mar 26 | E41: Aug 25 - Mar 26 | F41: Aug 24 - Jul 25 | G41: Feb 24 - Jul 24
A42: JDW Third Party Costs (variable) | B42: AWS Cloud Services | C42: The AWS Cloud platforms used to host production and DR app environments - myJDW, mySchedule, Authentication, Order & Pay App, Customer Accounts, Suggested Rotas, ChatBot. From June 2025, a gradual shift was started to move test and UAT environments to a separate Filter AWS environment (noted above), starting with Customer App and progressing to People Apps. This is expected to run at c.£5,000 per month, and the JDW AWS account will adjust down accordingly. | D42: =SUM(E42:G42) -> 1165839.1 | E42: =(84451.51+72874.06+79704.83+85130+91071.27+84454.29+78024.34+79476.31)*0.74 -> 484838.09 | F42: 512651 | G42: 168350 | I42: We are unsure exactly how much JDW pay and how the Bytes discounts work.
B43: Sendbird | C43: The application used in myChat to enable communication between employees. Billed on a “Monthly Active User” basis, with various other thresholds. Note: Costs converted at an exchange rate of $1=£0.74 | D43: =SUM(E43:G43) -> 194766 | E43: =7491*8 -> 59928 | F43: =7491*12 -> 89892 | G43: =7491*6 -> 44946 | I43: Will be charged March 2026
B44: WP Engine | C44: WP Engine is a managed WordPress hosting platform for websites built on WordPress. Corporate, Hotels, Investors, Careers, Franchises. Billed on a quarterly basis, with set usage levels and various overage charges. 5 year contract, commenced May 2024. | D44: =SUM(E44:G44) -> 196078.8 | E44: =7513.74*8 -> 60109.92 | F44: =SUM(7513.74*12)+726 -> 90890.88 | G44: =7513*6 -> 45078 | I44: Note a credit will be issued for 1 months payment, due to service interruption.
...

Sheet Summary
A1: Month: | C1: 45323 | D1: 45352 | E1: 45383 | F1: 45413 | G1: 45444 | H1: 45474 | I1: 45505 | J1: 45536 | K1: 45566 | L1: 45597 | M1: 45627 | N1: Running Total | O1: Check | Q1: 45658 | R1: 45689 | S1: 45717 | T1: 45748 | U1: 45778 | V1: 45809 | W1: 45839 | X1: 45870 | Y1: 45901 | Z1: 45931 | AA1: 45962 | AB1: 45992 | AC1: Running Total | AD1: Check | AF1: 46023 | AG1: 46054 | AH1: 46082 | AI1: Annual Running Total | AJ1: All Time Running Total | AL1: Check | AM1: Check
A3: Billing Amount (excl Third Party Services): | C3: ='Feb 24'!B3 -> 242579 | D3: ='Mar 24'!B3 -> 242579 | E3: ='Apr 24'!B3 -> 340813 | F3: ='May 24'!B3 -> 340813 | G3: ='Jun 24'!B3 -> 340813 | H3: ='Jul 24'!B3 -> 340813 | I3: ='Aug 24'!B3 -> 340813 | J3: ='Sep 24'!B3 -> 340813 | K3: ='Oct 24'!B3 -> 340813 | L3: ='Nov 24'!B3 -> 340813 | M3: ='Dec 24'!B3 -> 340813 | N3: =SUM(C3:M3) -> 3552475 | Q3: ='Jan 25'!B3 -> 340813 | R3: ='Feb 25'!B3 -> 340813 | S3: ='Mar 25'!B3 -> 340813 | T3: ='April 25'!B3 -> 340813 | U3: ='May 25'!B3 -> 340813 | V3: ='June 25'!B3 -> 340813 | W3: ='July 25'!B3 -> 340813 | X3: ='Aug 25'!B3 -> 340813 | Y3: ='Sep 25'!B3 -> 340813 | Z3: ='Oct 25'!B3 -> 353061 | AA3: ='Nov 25'!B3 -> 358179 | AB3: ='Dec 25'!B3 -> 378514 | AC3: =SUM(Q3:AB3) -> 4157071 | AF3: ='Jan - 26'!B3 -> 410756 | AG3: ='Feb - 26'!B3 -> 441376 | AH3: ='Mar - 26'!B3 -> 441376 | AI3: =+SUM(AF3,AG3,AH3) -> 1293508 | AJ3: =SUM(N3,AC3,AI3) -> 9003054 | AM3: =SUM(X3:AB3,AF3:AG3)-AM167 -> -441376
A4: Fixed Team Target Hours: | C4: ='Feb 24'!B4 -> 4016.25 | D4: ='Mar 24'!B4 -> 4016.25 | E4: ='Apr 24'!B4 -> 5984 | F4: ='May 24'!B4 -> 6256 | G4: ='Jun 24'!B4 -> 5440 | H4: ='Jul 24'!B4 -> 5984 | I4: ='Aug 24'!B4 -> 5984 | J4: ='Sep 24'!B4 -> 5712 | K4: ='Oct 24'!B4 -> 6256 | L4: ='Nov 24'!B4 -> 5712 | M4: ='Dec 24'!B4 -> 5984 | N4: =SUM(C4:M4) -> 61344.5 | Q4: ='Jan 25'!B4 -> 6256 | R4: ='Feb 25'!B4 -> 5440 | S4: ='Mar 25'!B4 -> 5712 | T4: ='April 25'!B4 -> 5984 | U4: ='May 25'!B4 -> 5984 | V4: ='June 25'!B4 -> 5712 | W4: ='July 25'!B4 -> 6256 | X4: ='Aug 25'!B4 -> 5712 | Y4: ='Sep 25'!B4 -> 5984 | Z4: ='Oct 25'!B4 -> 6549 | AA4: ='Nov 25'!B4 -> 5780 | AB4: ='Dec 25'!B4 -> 7038 | AC4: =SUM(Q4:AB4) -> 72407 | AF4: ='Jan - 26'!B4 -> 7480 | AG4: ='Feb - 26'!B4 -> 7310 | AH4: ='Mar - 26'!B4 -> 8041 | AI4: =SUM(AF4,AG4, AH4) -> 22831 | AJ4: =SUM(N4,AC4,AI4) -> 156582.5
A5: Fixed Team Recorded Hours: | C5: ='Feb 24'!B5 -> 4220.06 | D5: ='Mar 24'!B5 -> 4554.15 | E5: ='Apr 24'!B5 -> 5989.93 | F5: ='May 24'!B5 -> 6256.39 | G5: ='Jun 24'!B5 -> 5445.86 | H5: ='Jul 24'!B5 -> 6356.86 | I5: ='Aug 24'!B5 -> 6148.68 | J5: ='Sep 24'!B5 -> 5949.36 | K5: ='Oct 24'!B5 -> 6352.97 | L5: ='Nov 24'!B5 -> 5957.62 | M5: ='Dec 24'!B5 -> 6201.07 | N5: =SUM(C5:M5) -> 63432.95 | O5: =(D10+D61+C74)-N5 -> 0 | Q5: ='Jan 25'!B5 -> 6266.45 | R5: ='Feb 25'!B5 -> 5441.07 | S5: ='Mar 25'!B5 -> 5842.52 | T5: ='April 25'!B5 -> 6140.74 | U5: ='May 25'!B5 -> 6116.71 | V5: ='June 25'!B5 -> 5955.64 | W5: ='July 25'!B5 -> 6270.45 | X5: ='Aug 25'!B5 -> 5714.65 | Y5: ='Sep 25'!B5 -> 5995.92 | Z5: ='Oct 25'!B5 -> 6549.22 | AA5: ='Nov 25'!B5 -> 5784.74 | AB5: ='Dec 25'!B5 -> 7065.83 | AC5: =SUM(Q5:AB5) -> 73143.94 | AD5: =SUM(J10,J61,I74)-AC5 -> 0 | AF5: ='Jan - 26'!B5 -> 7539.75 | AG5: ='Feb - 26'!B5 -> 7346.48 | AH5: ='Mar - 26'!B5 -> 8047.028 | AI5: =SUM(AF5,AG5, AH5) -> 22933.258 | AJ5: =SUM(N5,AC5,AI5) -> 159510.15 | AK5: =SUM(P10+P61+O74)-AI5 -> 0 | AL5: =SUM(V10,V61,U74)-AJ5 -> 0
A6: Difference: | C6: ='Feb 24'!B6 -> 203.81 | D6: ='Mar 24'!B6 -> 537.9 | E6: ='Apr 24'!B6 -> 5.93 | F6: ='May 24'!B6 -> 0.39 | G6: ='Jun 24'!B6 -> 5.86 | H6: ='Jul 24'!B6 -> 372.86 | I6: ='Aug 24'!B6 -> 164.68 | J6: ='Sep 24'!B6 -> 237.36 | K6: ='Oct 24'!B6 -> 96.97 | L6: ='Nov 24'!B6 -> 245.62 | M6: ='Dec 24'!B6 -> 217.07 | N6: =SUM(C6:M6) -> 2088.45 | Q6: ='Jan 25'!B6 -> 10.45 | R6: ='Feb 25'!B6 -> 1.07 | S6: ='Mar 25'!B6 -> 130.52 | T6: ='April 25'!B6 -> 156.74 | U6: ='May 25'!B6 -> 132.71 | V6: ='June 25'!B6 -> 243.64 | W6: ='July 25'!B6 -> 14.45 | X6: ='Aug 25'!B6 -> 2.65 | Y6: ='Sep 25'!B6 -> 11.92 | Z6: ='Oct 25'!B6 -> 0.22 | AA6: ='Nov 25'!B6 -> 4.74 | AB6: ='Dec 25'!B6 -> 27.83 | AC6: =SUM(Q6:AB6) -> 736.94 | AF6: ='Jan - 26'!B6 -> 59.75 | AG6: ='Feb - 26'!B6 -> 36.48 | AH6: ='Mar - 26'!B6 -> 6.028 | AI6: =SUM(AF6,AG6, AH6) -> 102.258 | AJ6: =SUM(N6,AC6,AI6) -> 2927.648
A9: 2024 Programme Management | B9: Project Code | C9: Forecasted Hours | D9: Actual Hours | E9: Difference | G9: 2025 Programme Management | H9: Project Code | I9: Forecasted Hours | J9: Actual Hours | K9: Difference | M9: 2026 Programme Management | N9: Project Code | O9: Forecasted Hours | P9: Actual Hours | Q9: Difference | S9: Total Programme Management | T9: Project Code | U9: Forecasted Hours | V9: Actual Hours | W9: Difference
D10: =SUM('Feb 24'!S13)+('Mar 24'!T13)+('Apr 24'!T13)+('May 24'!T13)+('Jun 24'!T13)+('Jul 24'!T13)+('Aug 24'!T13)+('Sep 24'!T13)+('Oct 24'!T13)+('Nov 24'!T13)+('Dec 24'!T13) -> 20948.54 | J10: ='Jan 25'!T13+'Feb 25'!T13+'Mar 25'!T13+'April 25'!T13+'May 25'!T13+'June 25'!T13+'July 25'!T13+'Aug 25'!T13+'Sep 25'!T13+'Oct 25'!T13+'Nov 25'!T13+'Dec 25'!T13 -> 22751.6 | P10: =SUM('Jan - 26'!T13, 'Feb - 26'!T13, 'Mar - 26'!T13) -> 5595.358 | V10: =SUM(D10, J10,P10) -> 49295.498
A12: Reasearch & Planning | D12: =SUM('Feb 24'!C13:H13,'Feb 24'!J13)+SUM('Mar 24'!C13:H13,'Mar 24'!J13)+SUM('Apr 24'!C13:H13,'Apr 24'!J13)+SUM('May 24'!C13:H13,'May 24'!J13)+SUM('Jun 24'!C13:H13,'Jun 24'!J13)+SUM('Jul 24'!C13:H13,'Jul 24'!J13)+SUM('Aug 24'!C13:H13,'Aug 24'!J13)+SUM('Sep 24'!C13:H13,'Sep 24'!J13)+SUM('Oct 24'!C13:H13,'Oct 24'!J13)+SUM('Nov 24'!C13:H13,'Nov 24'!J13)+SUM('Dec 24'!C13:H13,'Dec 24'!J13) -> 6781.02 | G12: Reasearch & Planning | J12: =SUM('Jan 25'!C13,'Jan 25'!D13,'Jan 25'!E13,'Jan 25'!F13,'Jan 25'!G13,'Jan 25'!H13,'Jan 25'!J13)+ SUM('Feb 25'!C13,'Feb 25'!D13,'Feb 25'!E13,'Feb 25'!F13,'Feb 25'!G13,'Feb 25'!H13,'Feb 25'!J13)+ SUM('Mar 25'!C13,'Mar 25'!D13,'Mar 25'!E13,'Mar 25'!F13,'Mar 25'!G13,'Mar 25'!H13,'Mar 25'!J13)+ SUM('April 25'!C13,'April 25'!D13,'April 25'!E13,'April 25'!F13,'April 25'!G13,'April 25'!H13,'April 25'!J13)+SUM('May 25'!C13,'May 25'!D13,'May 25'!E13,'May 25'!F13,'May 25'!G13,'May 25'!H13,'May 25'!J13)+SUM('June 25'!C13,'June 25'!D13,'June 25'!F13,'June 25'!G13,'June 25'!H13,'June 25'!J13)+SUM('July 25'!C13,'July 25'!D13,'July 25'!E13,'July 25'!F13,'July 25'!G13,'July 25'!H13,'July 25'!J13)+SUM('Aug 25'!C13,'Aug 25'!D13,'Aug 25'!E13,'Aug 25'!F13,'Aug 25'!G13,'Aug 25'!H13,'Aug 25'!J13)+SUM('Sep 25'!C13,'Sep 25'!D13,'Sep 25'!F13,'Sep 25'!G13,'Sep 25'!H13,'Sep 25'!J13)+SUM('Oct 25'!C13,'Oct 25'!D13,'Oct 25'!E13,'Oct 25'!F13,'Oct 25'!G13,'Oct 25'!H13,'Oct 25'!J13)+SUM('Nov 25'!C13,'Nov 25'!D13,'Nov 25'!F13,'Nov 25'!G13,'Nov 25'!H13,'Nov 25'!J13)+SUM('Dec 25'!C13,'Dec 25'!D13,'Dec 25'!E13,'Dec 25'!F13,'Dec 25'!G13,'Dec 25'!H13,'Dec 25'!J13) -> 4650.41 | M12: Reasearch & Planning | P12: =SUM('Jan - 26'!C13,'Jan - 26'!D13,'Jan - 26'!E13,'Jan - 26'!F13,'Jan - 26'!G13,'Jan - 26'!H13,'Jan - 26'!J13)+SUM('Feb - 26'!C13,'Feb - 26'!D13,'Feb - 26'!E13,'Feb - 26'!F13,'Feb - 26'!G13,'Feb - 26'!H13,'Feb - 26'!J13)+SUM('Mar - 26'!C13,'Mar - 26'!D13,'Mar - 26'!F13,'Mar - 26'!G13,'Mar - 26'!J13) -> 1123.238 | S12: Reasearch & Planning | V12: =SUM(D12, J12+P12) -> 12554.668
A13: Includes industry research, feasibility and strategic design activities, programme management, financial management, strategic and senior meetings & reporting.
A15: Team Management Costs | D15: =SUM('Feb 24'!I13,'Feb 24'!K13,'Feb 24'!L13,'Feb 24'!M13,'Feb 24'!N13,'Feb 24'!O13,'Feb 24'!P13,'Feb 24'!Q13,'Feb 24'!R13)+SUM('Mar 24'!I13,'Mar 24'!K13,'Mar 24'!L13,'Mar 24'!M13,'Mar 24'!N13,'Mar 24'!O13,'Mar 24'!P13,'Mar 24'!Q13,'Mar 24'!R13,'Mar 24'!S13)+SUM('Apr 24'!I13,'Apr 24'!K13,'Apr 24'!L13,'Apr 24'!M13,'Apr 24'!N13,'Apr 24'!O13,'Apr 24'!P13,'Apr 24'!Q13,'Apr 24'!R13,'Apr 24'!S13)+SUM('May 24'!I13,'May 24'!K13,'May 24'!L13,'May 24'!M13,'May 24'!N13,'May 24'!O13,'May 24'!P13,'May 24'!Q13,'May 24'!R13,'May 24'!S13)+SUM('Jun 24'!I13,'Jun 24'!K13,'Jun 24'!L13,'Jun 24'!M13,'Jun 24'!N13,'Jun 24'!O13,'Jun 24'!P13,'Jun 24'!Q13,'Jun 24'!R13,'Jun 24'!S13)+SUM('Jul 24'!I13,'Jul 24'!K13,'Jul 24'!L13,'Jul 24'!M13,'Jul 24'!N13,'Jul 24'!O13,'Jul 24'!P13,'Jul 24'!Q13,'Jul 24'!R13,'Jul 24'!S13)+SUM('Aug 24'!I13,'Aug 24'!K13,'Aug 24'!L13,'Aug 24'!M13,'Aug 24'!N13,'Aug 24'!O13,'Aug 24'!P13,'Aug 24'!Q13,'Aug 24'!R13,'Aug 24'!S13)+SUM('Sep 24'!I13,'Sep 24'!K13,'Sep 24'!L13,'Sep 24'!M13,'Sep 24'!N13,'Sep 24'!O13,'Sep 24'!P13,'Sep 24'!Q13,'Sep 24'!R13,'Sep 24'!S13)+SUM('Oct 24'!I13,'Oct 24'!K13,'Oct 24'!L13,'Oct 24'!M13,'Oct 24'!N13,'Oct 24'!O13,'Oct 24'!P13,'Oct 24'!Q13,'Oct 24'!R13,'Oct 24'!S13)+SUM('Nov 24'!I13,'Nov 24'!K13,'Nov 24'!L13,'Nov 24'!M13,'Nov 24'!N13,'Nov 24'!O13,'Nov 24'!P13,'Nov 24'!Q13,'Nov 24'!R13,'Nov 24'!S13)+SUM('Dec 24'!I13,'Dec 24'!K13,'Dec 24'!L13,'Dec 24'!M13,'Dec 24'!N13,'Dec 24'!O13,'Dec 24'!P13,'Dec 24'!Q13,'Dec 24'!R13,'Dec 24'!S13) -> 14167.52 | G15: Team Management Costs | J15: =SUM('Jan 25'!I13,'Jan 25'!K13,'Jan 25'!L13,'Jan 25'!M13,'Jan 25'!N13,'Jan 25'!O13,'Jan 25'!P13,'Jan 25'!Q13,'Jan 25'!R13,'Jan 25'!S13)+ SUM('Feb 25'!I13,'Feb 25'!K13,'Feb 25'!L13,'Feb 25'!M13,'Feb 25'!N13,'Feb 25'!O13,'Feb 25'!P13,'Feb 25'!Q13,'Feb 25'!R13,'Feb 25'!S13)+ SUM('Mar 25'!I13,'Mar 25'!K13,'Mar 25'!L13,'Mar 25'!M13,'Mar 25'!N13,'Mar 25'!O13,'Mar 25'!P13,'Mar 25'!Q13,'Mar 25'!R13,'Mar 25'!S13)+ SUM('April 25'!I13,'April 25'!K13,'April 25'!L13,'April 25'!M13,'April 25'!N13,'April 25'!O13,'April 25'!P13,'April 25'!Q13,'April 25'!R13,'April 25'!S13)+SUM('May 25'!I13,'May 25'!K13,'May 25'!L13,'May 25'!M13,'May 25'!N13,'May 25'!O13,'May 25'!P13,'May 25'!Q13,'May 25'!S13)+SUM('June 25'!I13,'June 25'!K13,'June 25'!M13,'June 25'!N13,'June 25'!O13,'June 25'!P13,'June 25'!R13,'June 25'!S13)+SUM('July 25'!I13,'July 25'!K13,'July 25'!L13,'July 25'!M13,'July 25'!N13,'July 25'!O13,'July 25'!P13,'July 25'!Q13,'July 25'!R13,'July 25'!S13)+SUM('Aug 25'!I13,'Aug 25'!K13,'Aug 25'!L13,'Aug 25'!M13,'Aug 25'!N13,'Aug 25'!O13,'Aug 25'!P13,'Aug 25'!Q13,'Aug 25'!R13,'Aug 25'!S13)+SUM('Sep 25'!I13,'Sep 25'!K13,'Sep 25'!L13,'Sep 25'!M13,'Sep 25'!N13,'Sep 25'!O13,'Sep 25'!P13,'Sep 25'!R13,'Sep 25'!S13)+SUM('Oct 25'!I13,'Oct 25'!K13,'Oct 25'!L13,'Oct 25'!M13,'Oct 25'!N13,'Oct 25'!O13,'Oct 25'!P13,'Oct 25'!Q13,'Oct 25'!R13,'Oct 25'!S13)+SUM('Nov 25'!I13,'Nov 25'!K13,'Nov 25'!L13,'Nov 25'!M13,'Nov 25'!N13,'Nov 25'!O13,'Nov 25'!P13,'Nov 25'!R13)+SUM('Dec 25'!I13,'Dec 25'!K13,'Dec 25'!L13,'Dec 25'!M13,'Dec 25'!N13,'Dec 25'!O13,'Dec 25'!P13,'Dec 25'!Q13,'Dec 25'!R13,'Dec 25'!S13) -> 18101.19 | M15: Team Management Costs | P15: =SUM('Jan - 26'!I13,'Jan - 26'!K13,'Jan - 26'!L13,'Jan - 26'!M13,'Jan - 26'!N13,'Jan - 26'!O13,'Jan - 26'!P13,'Jan - 26'!Q13,'Jan - 26'!R13,'Jan - 26'!S13)+SUM('Feb - 26'!I13,'Feb - 26'!K13,'Feb - 26'!L13,'Feb - 26'!M13,'Feb - 26'!N13,'Feb - 26'!O13,'Feb - 26'!P13,'Feb - 26'!Q13,'Feb - 26'!R13,'Feb - 26'!S13)+SUM('Mar - 26'!I13,'Mar - 26'!K13,'Mar - 26'!L13,'Mar - 26'!M13,'Mar - 26'!N13,'Mar - 26'!O13,'Mar - 26'!P13,'Mar - 26'!R13,'Mar - 26'!S13) -> 4472.12 | S15: Team Management Costs | V15: =SUM(D15, J15,P15) -> 36740.83
A16: Includes staff recruitment, training, holidays, sick, other absences, travel and breaks for the equivalent of 32 full time Filter employees working on JDW related activities.
C17: Check | D17: =SUM(D12,D15)-D10 -> 0 | I17: Check | J17: =SUM(J15,J12)-J10 -> 0 | O17: Check | P17: =SUM(P15+P12)-P10 -> 0 | U17: Check | V17: =SUM(V15+V12)-V10 -> 0
A20: 2024 Projects | B20: Project Code | C20: Forecasted Hours | D20: Actual Hours | E20: Difference | G20: 2025 Projects | H20: Project Code | I20: Forecasted Hours | J20: Actual Hours | K20: Difference | M20: 2026 Projects | N20: Project Code | O20: Forecasted Hours | P20: Actual Hours | Q20: Difference | S20: Total Projects | T20: Project Code | U20: Forecasted Hours | V20: Actual Hours | W20: Difference
A21: Allergens Service | B21: I-000300 | D21: ='Feb 24'!J17+'Mar 24'!J17+'Apr 24'!J17+'May 24'!J17+'Jun 24'!J17+'Jul 24'!J17+'Aug 24'!J17+'Sep 24'!J17+'Oct 24'!J17+'Nov 24'!J17+'Dec 24'!J17 -> 511.58 | G21: Allergens Service | H21: I-000300 | J21: ='Jan 25'!J17+'Feb 25'!J17+'Mar 25'!J17+'April 25'!J17+'May 25'!J17+'June 25'!J17+'July 25'!J17+'Aug 25'!J17+'Sep 25'!J17+'Oct 25'!J17+'Nov 25'!J17+'Dec 25'!J17 -> 0 | M21: Allergens Service | N21: I-000300 | P21: =SUM('Jan - 26'!J17, 'Feb - 26'!J17,'Mar - 26'!J17) -> 0 | S21: Allergens Service | T21: I-000300 | V21: =SUM(D21,J21,P21) -> 511.58
A22: Authentication | B22: I-000312 | D22: ='Feb 24'!J18+'Mar 24'!J18+'Apr 24'!J18+'May 24'!J18+'Jun 24'!J18+'Jul 24'!J18+'Aug 24'!J18+'Sep 24'!J18+'Oct 24'!J18+'Nov 24'!J18+'Dec 24'!J18 -> 2038.87 | G22: Authentication | H22: I-000312 | J22: ='Jan 25'!J18+'Feb 25'!J18+'Mar 25'!J18+'April 25'!J18+'May 25'!J18+'June 25'!J18+'July 25'!J18+'Aug 25'!J18+'Sep 25'!J18+'Oct 25'!J18+'Nov 25'!J18+'Dec 25'!J18 -> 2693.56 | M22: Authentication | N22: I-000312 | P22: =SUM('Jan - 26'!J18, 'Feb - 26'!J18,'Mar - 26'!J18) -> 246.66 | S22: Authentication | T22: I-000312 | V22: =SUM(D22,J22,P22) -> 4979.09
A23: Available Ales on TV Screens | D23: ='Feb 24'!J19+'Mar 24'!J19+'Apr 24'!J19+'May 24'!J19+'Jun 24'!J19+'Jul 24'!J19+'Aug 24'!J19+'Sep 24'!J19+'Oct 24'!J19+'Nov 24'!J19+'Dec 24'!J19 -> 0 | G23: Available Ales on TV Screens | J23: ='Jan 25'!J19+'Feb 25'!J19+'Mar 25'!J19+'April 25'!J19+'May 25'!J19+'June 25'!J19+'July 25'!J19+'Aug 25'!J19+'Sep 25'!J19+'Oct 25'!J19+'Nov 25'!J19+'Dec 25'!J19 -> 65.33 | M23: Available Ales on TV Screens | P23: =SUM('Jan - 26'!J19, 'Feb - 26'!J19,'Mar - 26'!J19) -> 0 | S23: Available Ales on TV Screens | V23: =SUM(D23,J23,P23) -> 65.33
A24: Customer Information Screens | B24: I-000313 | D24: ='Feb 24'!J20+'Mar 24'!J20+'Apr 24'!J20+'May 24'!J20+'Jun 24'!J20+'Jul 24'!J20+'Aug 24'!J20+'Sep 24'!J20+'Oct 24'!J20+'Nov 24'!J20+'Dec 24'!J20 -> 418.91 | G24: Customer Information Screens | H24: I-000313 | J24: ='Jan 25'!J20+'Feb 25'!J20+'Mar 25'!J20+'April 25'!J20+'May 25'!J20+'June 25'!J20+'July 25'!J20+'Aug 25'!J20+'Sep 25'!J20+'Oct 25'!J20+'Nov 25'!J20+'Dec 25'!J20 -> 43.42 | M24: Customer Information Screens | N24: I-000313 | P24: =SUM('Jan - 26'!J20, 'Feb - 26'!J20,'Mar - 26'!J20) -> 1.25 | S24: Customer Information Screens | T24: I-000313 | V24: =SUM(D24,J24,P24) -> 463.58
A25: Corporate Website Replatform Build | B25: I-000300 | D25: ='Feb 24'!J21+'Mar 24'!J21+'Apr 24'!J21+'May 24'!J21+'Jun 24'!J21+'Jul 24'!J21+'Aug 24'!J21+'Sep 24'!J21+'Oct 24'!J21+'Nov 24'!J21+'Dec 24'!J21 -> 1786.84 | G25: Corporate Website Replatform Build | H25: I-000300 | J25: ='Jan 25'!J21+'Feb 25'!J21+'Mar 25'!J21+'April 25'!J21+'May 25'!J21+'June 25'!J21+'July 25'!J21+'Aug 25'!J21+'Sep 25'!J21+'Oct 25'!J21+'Nov 25'!J21+'Dec 25'!J21 -> 1.75 | M25: Corporate Website Replatform Build | N25: I-000300 | P25: =SUM('Jan - 26'!J21, 'Feb - 26'!J21,'Mar - 26'!J21) -> 0 | S25: Corporate Website Replatform Build | T25: I-000300 | V25: =SUM(D25,J25,P25) -> 1788.59
A26: Customer Accounts Planning | B26: I-000311 | D26: ='Feb 24'!J22+'Mar 24'!J22+'Apr 24'!J22+'May 24'!J22+'Jun 24'!J22+'Jul 24'!J22+'Aug 24'!J22+'Sep 24'!J22+'Oct 24'!J22+'Nov 24'!J22+'Dec 24'!J22 -> 1152.32 | G26: Customer Accounts Planning | H26: I-000311 | J26: ='Jan 25'!J22+'Feb 25'!J22+'Mar 25'!J22+'April 25'!J22+'May 25'!J22+'June 25'!J22+'July 25'!J22+'Aug 25'!J22+'Sep 25'!J22+'Oct 25'!J22+'Nov 25'!J22+'Dec 25'!J22 -> 1261.2 | M26: Customer Accounts Planning | N26: I-000311 | P26: =SUM('Jan - 26'!J22, 'Feb - 26'!J22,'Mar - 26'!J22) -> 34 | S26: Customer Accounts Planning | T26: I-000311 | V26: =SUM(D26,J26,P26) -> 2447.52
A27: Customer App - Ibersol Franchise Integration | D27: ='Feb 24'!J23+'Mar 24'!J23+'Apr 24'!J23+'May 24'!J23+'Jun 24'!J23+'Jul 24'!J23+'Aug 24'!J23+'Sep 24'!J23+'Oct 24'!J23+'Nov 24'!J23+'Dec 24'!J23 -> 0 | G27: Customer App - Ibersol Franchise Integration | J27: ='Jan 25'!J23+'Feb 25'!J23+'Mar 25'!J23+'April 25'!J23+'May 25'!J23+'June 25'!J23+'July 25'!J23+'Aug 25'!J23+'Sep 25'!J23+'Oct 25'!J23+'Nov 25'!J23+'Dec 25'!J23 -> 0 | M27: Customer App - Ibersol Franchise Integration | P27: =SUM('Jan - 26'!J23, 'Feb - 26'!J23,'Mar - 26'!J23) -> 137.83 | S27: Customer App - Ibersol Franchise Integration | V27: =SUM(D27,J27,P27) -> 137.83
A28: Customer App - Lagardere Franchise Integration | D28: ='Feb 24'!J24+'Mar 24'!J24+'Apr 24'!J24+'May 24'!J24+'Jun 24'!J24+'Jul 24'!J24+'Aug 24'!J24+'Sep 24'!J24+'Oct 24'!J24+'Nov 24'!J24+'Dec 24'!J24 -> 0 | G28: Customer App - Lagardere Franchise Integration | J28: ='Jan 25'!J24+'Feb 25'!J24+'Mar 25'!J24+'April 25'!J24+'May 25'!J24+'June 25'!J24+'July 25'!J24+'Aug 25'!J24+'Sep 25'!J24+'Oct 25'!J24+'Nov 25'!J24+'Dec 25'!J24 -> 0 | M28: Customer App - Lagardere Franchise Integration | P28: =SUM('Jan - 26'!J24, 'Feb - 26'!J24,'Mar - 26'!J24) -> 493.41 | S28: Customer App - Lagardere Franchise Integration | V28: =SUM(D28,J28,P28) -> 493.41
A29: Customer App / PWA / App Manager | B29: I-000287 | D29: ='Feb 24'!J25+'Mar 24'!J25+'Apr 24'!J25+'May 24'!J25+'Jun 24'!J25+'Jul 24'!J25+'Aug 24'!J25+'Sep 24'!J25+'Oct 24'!J25+'Nov 24'!J25+'Dec 24'!J25 -> 15632.11 | G29: Customer App / PWA / App Manager | H29: I-000287 | J29: ='Jan 25'!J25+'Feb 25'!J25+'Mar 25'!J25+'April 25'!J25+'May 25'!J25+'June 25'!J25+'July 25'!J25+'Aug 25'!J25+'Sep 25'!J25+'Oct 25'!J25+'Nov 25'!J25+'Dec 25'!J25 -> 11613.94 | M29: Customer App / PWA / App Manager | N29: I-000287 | P29: =SUM('Jan - 26'!J25, 'Feb - 26'!J25,'Mar - 26'!J25) -> 4297.95 | S29: Customer App / PWA / App Manager | T29: I-000287 | V29: =SUM(D29,J29,P29) -> 31544
A30: Customer App UX/UI Redesign | D30: ='Feb 24'!J26+'Mar 24'!J26+'Apr 24'!J26+'May 24'!J26+'Jun 24'!J26+'Jul 24'!J26+'Aug 24'!J26+'Sep 24'!J26+'Oct 24'!J26+'Nov 24'!J26+'Dec 24'!J26 -> 0 | G30: Customer App UX/UI Redesign | J30: ='Jan 25'!J26+'Feb 25'!J26+'Mar 25'!J26+'April 25'!J26+'May 25'!J26+'June 25'!J26+'July 25'!J26+'Aug 25'!J26+'Sep 25'!J26+'Oct 25'!J26+'Nov 25'!J26+'Dec 25'!J26 -> 938.24 | M30: Customer App UX/UI Redesign | P30: =SUM('Jan - 26'!J26, 'Feb - 26'!J26,'Mar - 26'!J26) -> 843.94 | S30: Customer App UX/UI Redesign | V30: =SUM(D30,J30,P30) -> 1782.18
A31: Customer Planning | D31: ='Feb 24'!J27+'Mar 24'!J27+'Apr 24'!J27+'May 24'!J27+'Jun 24'!J27+'Jul 24'!J27+'Aug 24'!J27+'Sep 24'!J27+'Oct 24'!J27+'Nov 24'!J27+'Dec 24'!J27 -> 0 | G31: Customer Planning | J31: ='Jan 25'!J27+'Feb 25'!J27+'Mar 25'!J27+'April 25'!J27+'May 25'!J27+'June 25'!J27+'July 25'!J27+'Aug 25'!J27+'Sep 25'!J27+'Oct 25'!J27+'Nov 25'!J27+'Dec 25'!J27 -> 0 | M31: Customer Planning | P31: =SUM('Jan - 26'!J27, 'Feb - 26'!J27,'Mar - 26'!J27) -> 0 | S31: Customer Planning | V31: =SUM(D31,J31,P31) -> 0
A32: Digital Pub Records | B32: I-000314 | D32: ='Feb 24'!J28+'Mar 24'!J28+'Apr 24'!J28+'May 24'!J28+'Jun 24'!J28+'Jul 24'!J28+'Aug 24'!J28+'Sep 24'!J28+'Oct 24'!J28+'Nov 24'!J28+'Dec 24'!J28 -> 624.27 | G32: Digital Pub Records | H32: I-000314 | J32: ='Jan 25'!J28+'Feb 25'!J28+'Mar 25'!J28+'April 25'!J28+'May 25'!J28+'June 25'!J28+'July 25'!J28+'Aug 25'!J28+'Sep 25'!J28+'Oct 25'!J28+'Nov 25'!J28+'Dec 25'!J28 -> 2846.78 | M32: Digital Pub Records | N32: I-000314 | P32: =SUM('Jan - 26'!J28, 'Feb - 26'!J28,'Mar - 26'!J28) -> 0 | S32: Digital Pub Records | T32: I-000314 | V32: =SUM(D32,J32,P32) -> 3471.05
A33: Digital Vouchers | D33: ='Feb 24'!J29+'Mar 24'!J29+'Apr 24'!J29+'May 24'!J29+'Jun 24'!J29+'Jul 24'!J29+'Aug 24'!J29+'Sep 24'!J29+'Oct 24'!J29+'Nov 24'!J29+'Dec 24'!J29 -> 0 | G33: Digital Vouchers | J33: ='Jan 25'!J29+'Feb 25'!J29+'Mar 25'!J29+'April 25'!J29+'May 25'!J29+'June 25'!J29+'July 25'!J29+'Aug 25'!J29+'Sep 25'!J29+'Oct 25'!J29+'Nov 25'!J29+'Dec 25'!J29 -> 341.17 | M33: Digital Vouchers | P33: =SUM('Jan - 26'!J29, 'Feb - 26'!J29,'Mar - 26'!J29) -> 221.43 | S33: Digital Vouchers | V33: =SUM(D33,J33,P33) -> 562.6
A34: Disaster Recovery & Business Continuity | B34: I-000315 | D34: ='Feb 24'!J30+'Mar 24'!J30+'Apr 24'!J30+'May 24'!J30+'Jun 24'!J30+'Jul 24'!J30+'Aug 24'!J30+'Sep 24'!J30+'Oct 24'!J30+'Nov 24'!J30+'Dec 24'!J30 -> 63.25 | G34: Disaster Recovery & Business Continuity | H34: I-000315 | J34: ='Jan 25'!J30+'Feb 25'!J30+'Mar 25'!J30+'April 25'!J30+'May 25'!J30+'June 25'!J30+'July 25'!J30+'Aug 25'!J30+'Sep 25'!J30+'Oct 25'!J30+'Nov 25'!J30+'Dec 25'!J30 -> 128.1 | M34: Disaster Recovery & Business Continuity | N34: I-000315 | P34: =SUM('Jan - 26'!J30, 'Feb - 26'!J30,'Mar - 26'!J30) -> 77.34 | S34: Disaster Recovery & Business Continuity | T34: I-000315 | V34: =SUM(D34,J34,P34) -> 268.69
A35: Employee Digital Record | B35: I-000316 | D35: ='Feb 24'!J31+'Mar 24'!J31+'Apr 24'!J31+'May 24'!J31+'Jun 24'!J31+'Jul 24'!J31+'Aug 24'!J31+'Sep 24'!J31+'Oct 24'!J31+'Nov 24'!J31+'Dec 24'!J31 -> 601.93 | G35: Employee Digital Record | H35: I-000316 | J35: ='Jan 25'!J31+'Feb 25'!J31+'Mar 25'!J31+'April 25'!J31+'May 25'!J31+'June 25'!J31+'July 25'!J31+'Aug 25'!J31+'Sep 25'!J31+'Oct 25'!J31+'Nov 25'!J31+'Dec 25'!J31 -> 1714.44 | M35: Employee Digital Record | N35: I-000316 | P35: =SUM('Jan - 26'!J31, 'Feb - 26'!J31,'Mar - 26'!J31) -> 433.08 | S35: Employee Digital Record | T35: I-000316 | V35: =SUM(D35,J35,P35) -> 2749.45
A36: Employee Verification (with WISDOM) | B36: I-000274 | D36: ='Feb 24'!J32+'Mar 24'!J32+'Apr 24'!J32+'May 24'!J32+'Jun 24'!J32+'Jul 24'!J32+'Aug 24'!J32+'Sep 24'!J32+'Oct 24'!J32+'Nov 24'!J32+'Dec 24'!J32 -> 243.93 | G36: Employee Verification (with WISDOM) | H36: I-000274 | J36: ='Jan 25'!J32+'Feb 25'!J32+'Mar 25'!J32+'April 25'!J32+'May 25'!J32+'June 25'!J32+'July 25'!J32+'Aug 25'!J32+'Sep 25'!J32+'Oct 25'!J32+'Nov 25'!J32+'Dec 25'!J32 -> 0 | M36: Employee Verification (with WISDOM) | N36: I-000274 | P36: =SUM('Jan - 26'!J32, 'Feb - 26'!J32,'Mar - 26'!J32) -> 0 | S36: Employee Verification (with WISDOM) | T36: I-000274 | V36: =SUM(D36,J36,P36) -> 243.93
A37: Franchises Customer App | D37: ='Feb 24'!J33+'Mar 24'!J33+'Apr 24'!J33+'May 24'!J33+'Jun 24'!J33+'Jul 24'!J33+'Aug 24'!J33+'Sep 24'!J33+'Oct 24'!J33+'Nov 24'!J33+'Dec 24'!J33 -> 1064.78 | G37: Franchises Customer App | J37: ='Jan 25'!J33+'Feb 25'!J33+'Mar 25'!J33+'April 25'!J33+'May 25'!J33+'June 25'!J33+'July 25'!J33+'Aug 25'!J33+'Sep 25'!J33+'Oct 25'!J33+'Nov 25'!J33+'Dec 25'!J33 -> 4007.58 | M37: Franchises Customer App | P37: =SUM('Jan - 26'!J33, 'Feb - 26'!J33,'Mar - 26'!J33) -> 915.72 | S37: Franchises Customer App | V37: =SUM(D37,J37,P37) -> 5988.08
A38: Franchises myJDW | D38: ='Feb 24'!J34+'Mar 24'!J34+'Apr 24'!J34+'May 24'!J34+'Jun 24'!J34+'Jul 24'!J34+'Aug 24'!J34+'Sep 24'!J34+'Oct 24'!J34+'Nov 24'!J34+'Dec 24'!J34 -> 1.5 | G38: Franchises myJDW | J38: ='Jan 25'!J34+'Feb 25'!J34+'Mar 25'!J34+'April 25'!J34+'May 25'!J34+'June 25'!J34+'July 25'!J34+'Aug 25'!J34+'Sep 25'!J34+'Oct 25'!J34+'Nov 25'!J34+'Dec 25'!J34 -> 264.61 | M38: Franchises myJDW | P38: =SUM('Jan - 26'!J34, 'Feb - 26'!J34,'Mar - 26'!J34) -> 1821.89 | S38: Franchises myJDW | V38: =SUM(D38,J38,P38) -> 2088
A39: Franchises mySchedule | D39: ='Feb 24'!J35+'Mar 24'!J35+'Apr 24'!J35+'May 24'!J35+'Jun 24'!J35+'Jul 24'!J35+'Aug 24'!J35+'Sep 24'!J35+'Oct 24'!J35+'Nov 24'!J35+'Dec 24'!J35 -> 2 | G39: Franchises mySchedule | J39: ='Jan 25'!J35+'Feb 25'!J35+'Mar 25'!J35+'April 25'!J35+'May 25'!J35+'June 25'!J35+'July 25'!J35+'Aug 25'!J35+'Sep 25'!J35+'Oct 25'!J35+'Nov 25'!J35+'Dec 25'!J35 -> 52.25 | M39: Franchises mySchedule | P39: =SUM('Jan - 26'!J35, 'Feb - 26'!J35,'Mar - 26'!J35) -> 153.73 | S39: Franchises mySchedule | V39: =SUM(D39,J39,P39) -> 207.98
A40: Franchises WordPress Websites | D40: ='Feb 24'!J36+'Mar 24'!J36+'Apr 24'!J36+'May 24'!J36+'Jun 24'!J36+'Jul 24'!J36+'Aug 24'!J36+'Sep 24'!J36+'Oct 24'!J36+'Nov 24'!J36+'Dec 24'!J36 -> 0 | G40: Franchises WordPress Websites | J40: ='Jan 25'!J36+'Feb 25'!J36+'Mar 25'!J36+'April 25'!J36+'May 25'!J36+'June 25'!J36+'July 25'!J36+'Aug 25'!J36+'Sep 25'!J36+'Oct 25'!J36+'Nov 25'!J36+'Dec 25'!J36 -> 0 | M40: Franchises WordPress Websites | P40: =SUM('Jan - 26'!J36, 'Feb - 26'!J36,'Mar - 26'!J36) -> 114.33 | S40: Franchises WordPress Websites | V40: =SUM(D40,J40,P40) -> 114.33
A41: Hotels HLS Integration | D41: ='Feb 24'!J37+'Mar 24'!J37+'Apr 24'!J37+'May 24'!J37+'Jun 24'!J37+'Jul 24'!J37+'Aug 24'!J37+'Sep 24'!J37+'Oct 24'!J37+'Nov 24'!J37+'Dec 24'!J37 -> 0 | G41: Hotels HLS Integration | J41: ='Jan 25'!J37+'Feb 25'!J37+'Mar 25'!J37+'April 25'!J37+'May 25'!J37+'June 25'!J37+'July 25'!J37+'Aug 25'!J37+'Sep 25'!J37+'Oct 25'!J37+'Nov 25'!J37+'Dec 25'!J37 -> 122.18 | M41: Hotels HLS Integration | P41: =SUM('Jan - 26'!J37, 'Feb - 26'!J37,'Mar - 26'!J37) -> 15.75 | S41: Hotels HLS Integration | V41: =SUM(D41,J41,P41) -> 137.93
A42: Hotels Price Comparison | B42: I-000317 | D42: ='Feb 24'!J38+'Mar 24'!J38+'Apr 24'!J38+'May 24'!J38+'Jun 24'!J38+'Jul 24'!J38+'Aug 24'!J38+'Sep 24'!J38+'Oct 24'!J38+'Nov 24'!J38+'Dec 24'!J38 -> 3.5 | G42: Hotels Price Comparison | H42: I-000317 | J42: ='Jan 25'!J38+'Feb 25'!J38+'Mar 25'!J38+'April 25'!J38+'May 25'!J38+'June 25'!J38+'July 25'!J38+'Aug 25'!J38+'Sep 25'!J38+'Oct 25'!J38+'Nov 25'!J38+'Dec 25'!J38 -> 0 | M42: Hotels Price Comparison | N42: I-000317 | P42: =SUM('Jan - 26'!J38, 'Feb - 26'!J38,'Mar - 26'!J38) -> 0 | S42: Hotels Price Comparison | T42: I-000317 | V42: =SUM(D42,J42,P42) -> 3.5
A43: Intelligence PoC | B43: I-000318 | D43: ='Feb 24'!J39+'Mar 24'!J39+'Apr 24'!J39+'May 24'!J39+'Jun 24'!J39+'Jul 24'!J39+'Aug 24'!J39+'Sep 24'!J39+'Oct 24'!J39+'Nov 24'!J39+'Dec 24'!J39 -> 1188.79 | G43: Intelligence PoC | H43: I-000318 | J43: ='Jan 25'!J39+'Feb 25'!J39+'Mar 25'!J39+'April 25'!J39+'May 25'!J39+'June 25'!J39+'July 25'!J39+'Aug 25'!J39+'Sep 25'!J39+'Oct 25'!J39+'Nov 25'!J39+'Dec 25'!J39 -> 2370.59 | M43: Intelligence PoC | N43: I-000318 | P43: =SUM('Jan - 26'!J39, 'Feb - 26'!J39,'Mar - 26'!J39) -> 792.65 | S43: Intelligence PoC | T43: I-000318 | V43: =SUM(D43,J43,P43) -> 4352.03
A44: Microsoft Office Replacement | D44: ='Feb 24'!J40+'Mar 24'!J40+'Apr 24'!J40+'May 24'!J40+'Jun 24'!J40+'Jul 24'!J40+'Aug 24'!J40+'Sep 24'!J40+'Oct 24'!J40+'Nov 24'!J40+'Dec 24'!J40 -> 15.5 | G44: Microsoft Office Replacement | J44: ='Jan 25'!J40+'Feb 25'!J40+'Mar 25'!J40+'April 25'!J40+'May 25'!J40+'June 25'!J40+'July 25'!J40+'Aug 25'!J40+'Sep 25'!J40+'Oct 25'!J40+'Nov 25'!J40+'Dec 25'!J40 -> 302.92 | M44: Microsoft Office Replacement | P44: =SUM('Jan - 26'!J40, 'Feb - 26'!J40,'Mar - 26'!J40) -> 29.5 | S44: Microsoft Office Replacement | V44: =SUM(D44,J44,P44) -> 347.92
A45: myETL | D45: ='Feb 24'!J41+'Mar 24'!J41+'Apr 24'!J41+'May 24'!J41+'Jun 24'!J41+'Jul 24'!J41+'Aug 24'!J41+'Sep 24'!J41+'Oct 24'!J41+'Nov 24'!J41+'Dec 24'!J41 -> 0 | G45: myETL | J45: ='Jan 25'!J41+'Feb 25'!J41+'Mar 25'!J41+'April 25'!J41+'May 25'!J41+'June 25'!J41+'July 25'!J41+'Aug 25'!J41+'Sep 25'!J41+'Oct 25'!J41+'Nov 25'!J41+'Dec 25'!J41 -> 0 | M45: myETL | P45: =SUM('Jan - 26'!J41, 'Feb - 26'!J41,'Mar - 26'!J41) -> 444.42 | S45: myETL | V45: =SUM(D45,J45,P45) -> 444.42
A46: myPub | B46: I-000319 | D46: ='Feb 24'!J42+'Mar 24'!J42+'Apr 24'!J42+'May 24'!J42+'Jun 24'!J42+'Jul 24'!J42+'Aug 24'!J42+'Sep 24'!J42+'Oct 24'!J42+'Nov 24'!J42+'Dec 24'!J42 -> 355.08 | G46: myPub | H46: I-000319 | J46: ='Jan 25'!J42+'Feb 25'!J42+'Mar 25'!J42+'April 25'!J42+'May 25'!J42+'June 25'!J42+'July 25'!J42+'Aug 25'!J42+'Sep 25'!J42+'Oct 25'!J42+'Nov 25'!J42+'Dec 25'!J42 -> 313.64 | M46: myPub | N46: I-000319 | P46: =SUM('Jan - 26'!J42, 'Feb - 26'!J42,'Mar - 26'!J42) -> 450.99 | S46: myPub | T46: I-000319 | V46: =SUM(D46,J46,P46) -> 1119.71
A47: myDiscounts App | B47: I-000320 | D47: ='Feb 24'!J43+'Mar 24'!J43+'Apr 24'!J43+'May 24'!J43+'Jun 24'!J43+'Jul 24'!J43+'Aug 24'!J43+'Sep 24'!J43+'Oct 24'!J43+'Nov 24'!J43+'Dec 24'!J43 -> 46.5 | G47: myDiscounts App | H47: I-000320 | J47: ='Jan 25'!J43+'Feb 25'!J43+'Mar 25'!J43+'April 25'!J43+'May 25'!J43+'June 25'!J43+'July 25'!J43+'Aug 25'!J43+'Sep 25'!J43+'Oct 25'!J43+'Nov 25'!J43+'Dec 25'!J43 -> 0 | M47: myDiscounts App | N47: I-000320 | P47: =SUM('Jan - 26'!J43, 'Feb - 26'!J43,'Mar - 26'!J43) -> 0 | S47: myDiscounts App | T47: I-000320 | V47: =SUM(D47,J47,P47) -> 46.5
...

Sheet Feb 24
A1: Month: | B1: 45323
A3: Dedicated Team Billing: | B3: =B9+B60 -> 242579
A4: Fixed Team Target Hours: | B4: =SUM(22.5*8.5)*21 -> 4016.25 | C4: 25 people (20 dedicated, 5 part-time)
A5: Fixed Team Recorded Hours: | B5: =S13+J57+G72 -> 4220.06
A6: Difference: | B6: =B5-B4 -> 203.81
A9: Planning, Development & Delivery | B9: 222986
C10: R&P | D10: R&P | E10: R&P | F10: R&P | G10: R&P | H10: R&P | I10: TMC | J10: R&P | K10: TMC | L10: TMC | M10: TMC | N10: TMC | O10: TMC | P10: TMC | Q10: TMC | R10: TMC
A11: Programme Management Hours | B11: Project Code | C11: Planning | D11: Project Management, Meetings & Reporting | E11: Design | F11: Admin | G11: Systems Admin | H11: Research | I11: Training | J11: Finance | K11: HR | L11: Recruitment | M11: Travel | N11: Break | O11: Lunch | P11: Holiday | Q11: Sick | R11: Other Absence | S11: Total
C13: 41 | D13: 235.99 | E13: =SUM(E12) -> 0 | F13: 78.08 | G13: 129.95 | H13: 11.51 | I13: 93.77 | J13: 19 | K13: 18.33 | L13: 59.92 | M13: 6.25 | N13: 47.6 | O13: 248.38 | P13: 89.75 | Q13: 35.25 | R13: 17 | S13: =SUM(C13:R13) -> 1131.78
A16: Projects Hours | B16: Project Code | C16: Development | D16: Project Management, Meetings & Reporting | E16: Testing | F16: Planning | G16: Systems Admin | H16: Design | I16: Release | J16: Total
A17: Allergens Service | B17: I-000300 | C17: 74.82 | D17: 30.94 | E17: 0.25 | J17: =SUM(C17:I17) -> 106.01
A18: Authentication | B18: I-000312 | F18: 12.5 | J18: =SUM(C18:I18) -> 12.5
A19: Available Ales on TV Screens | J19: =SUM(C19:I19) -> 0
A20: Customer Information Screens | B20: I-000313 | C20: 11.75 | D20: 2.75 | E20: 2 | F20: 1 | J20: =SUM(C20:I20) -> 17.5
A21: Corporate Website Replatform Build | B21: I-000300 | C21: 176.5 | D21: 45.83 | F21: 0.75 | G21: 1.25 | H21: 2.75 | J21: =SUM(C21:I21) -> 227.08
A22: Customer Accounts Planning | B22: I-000311 | C22: 4.92 | D22: 3.25 | F22: 6 | J22: =SUM(C22:I22) -> 14.17
A23: Customer App - Ibersol Franchise Integration
A24: Customer App - Lagardere Franchise Integration
A25: Customer App / PWA / App Manager | B25: I-000287 | C25: 401.89 | D25: =148.18+0.5 -> 148.68 | E25: =311.75+1.5 -> 313.25 | F25: =22+18 -> 40 | G25: 33.43 | H25: 18.5 | I25: 0.75 | J25: =SUM(C25:I25) -> 956.5
A26: Customer App UX/UI Redesign | J26: =SUM(C26:I26) -> 0
A27: Customer Planning
A28: Digital Pub Records | B28: I-000314 | J28: =SUM(C28:I28) -> 0
A29: Digital Vouchers
A30: Disaster Recovery & Business Continuity | B30: I-000315 | J30: =SUM(C30:I30) -> 0
A31: Employee Digital Records | B31: I-000316 | J31: =SUM(C31:I31) -> 0
A32: Employee Verification (with WISDOM) | B32: I-000274 | D32: 12.25 | J32: =SUM(C32:I32) -> 12.25
A33: Franchises Customer App | F33: 9 | J33: =SUM(C33:I33) -> 9
A34: Franchises myJDW | J34: =SUM(C34:I34) -> 0
A35: Franchises mySchedule | J35: =SUM(C35:I35) -> 0
A36: Franchises WordPress Websites
A37: Hotels HLS Integration | J37: =SUM(C37:I37) -> 0
A38: Hotels Price Comparison | B38: I-000317 | J38: =SUM(C38:I38) -> 0
A39: Intelligence PoC | B39: I-000318 | J39: =SUM(C39:I39) -> 0
A40: Microsoft Office Replacement | J40: =SUM(C40:I40) -> 0
A41: myETL
A42: myPub | B42: I-000319 | J42: =SUM(C42:I42) -> 0
A43: myDiscounts App | B43: I-000320 | D43: 8.75 | F43: 4 | H43: 10.25 | J43: =SUM(C43:I43) -> 23
A44: myJDW | B44: I-000239 | C44: 406.15 | D44: 166.51 | E44: 1 | F44: 86.81 | G44: 0.38 | H44: 3.25 | J44: =SUM(C44:I44) -> 664.1
A45: mySchedule | B45: I-000271 | C45: 266.89 | D45: 101.16 | E45: 166.74 | F45: 83.4 | G45: 1.58 | H45: 7 | I45: 7.33 | J45: =SUM(C45:I45) -> 634.1
A46: People Planning
...

Sheet Mar 24
A1: Month: | B1: 45352
A3: Dedicated Team Billing: | B3: =B9+B60 -> 242579
A4: Fixed Team Target Hours: | B4: =SUM(22.5*8.5)*21 -> 4016.25 | C4: 25 people (20 dedicated, 5 part-time)
A5: Fixed Team Recorded Hours: | B5: =T13+J57+G72 -> 4554.15
A6: Difference: | B6: =B5-B4 -> 537.9
A9: Planning, Development & Delivery | B9: 222986
C10: R&P | D10: R&P | E10: R&P | F10: R&P | G10: R&P | H10: R&P | I10: TMC | J10: R&P | K10: TMC | L10: TMC | M10: TMC | N10: TMC | O10: TMC | P10: TMC | Q10: TMC | R10: TMC | S10: TMC
A11: Programme Management Hours | B11: Project Code | C11: Planning | D11: Project Management, Meetings & Reporting | E11: Design | F11: Admin | G11: Systems Admin | H11: Research | I11: Training | J11: Finance | K11: HR | L11: Recruitment | M11: Travel | N11: Break | O11: Lunch | P11: Holiday | Q11: Bank Holiday | R11: Sick | S11: Other Absence | T11: Total
C13: 121.75 | D13: 301.76 | E13: =SUM(E12) -> 0 | F13: 31.32 | G13: 156.41 | H13: 6 | I13: 69.52 | J13: 7.25 | K13: 22.27 | L13: 50.02 | M13: 11.75 | N13: 33.84 | O13: 266.25 | P13: 170 | Q13: 193.5 | R13: 35.75 | S13: 82 | T13: =SUM(C13:S13) -> 1559.39
A16: Projects Hours | B16: Project Code | C16: Development | D16: Project Management, Meetings & Reporting | E16: Testing | F16: Planning | G16: Systems Admin | H16: Design | I16: Release | J16: Total
A17: Allergens Service | B17: I-000300 | C17: 37.78 | D17: 43.81 | E17: 10.46 | F17: 3 | G17: 2.33 | H17: 0.5 | I17: 3.42 | J17: =SUM(C17:I17) -> 101.3
A18: Authentication | B18: I-000312 | D18: 16.89 | F18: 84.33 | H18: 10.75 | J18: =SUM(C18:I18) -> 111.97
A19: Available Ales on TV Screens | J19: =SUM(C19:I19) -> 0
A20: Customer Information Screens | B20: I-000313 | C20: 5.5 | D20: 0.25 | E20: 1 | F20: 4.25 | J20: =SUM(C20:I20) -> 11
A21: Corporate Website Replatform Build | B21: I-000300 | C21: 108 | D21: 26.5 | F21: 4.25 | G21: 0.25 | H21: 0.75 | J21: =SUM(C21:I21) -> 139.75
A22: Customer Accounts Planning | B22: I-000311 | C22: 94.75 | D22: 14.03 | E22: 1.75 | F22: 1 | J22: =SUM(C22:I22) -> 111.53
A23: Customer App - Ibersol Franchise Integration
A24: Customer App - Lagardere Franchise Integration
A25: Customer App / PWA / App Manager | B25: I-000287 | C25: =521.62+1.17 -> 522.79 | D25: =209.73+6.5 -> 216.23 | E25: =223.35+1.25 -> 224.6 | F25: 40.62 | G25: 114.2 | H25: =17.25+0.75 -> 18 | I25: 8.5 | J25: =SUM(C25:I25) -> 1144.94
A26: Customer App UX/UI Redesign | J26: =SUM(C26:I26) -> 0
A27: Customer Planning
A28: Digital Pub Records | B28: I-000314 | J28: =SUM(C28:I28) -> 0
A29: Digital Vouchers | J29: =SUM(C29:I29) -> 0
A30: Disaster Recovery & Business Continuity | B30: I-000315 | J30: =SUM(C30:I30) -> 0
A31: Employee Digital Records | B31: I-000316 | F31: 11 | J31: =SUM(C31:I31) -> 11
A32: Employee Verification (with WISDOM) | B32: I-000274 | C32: 6.45 | D32: 8.96 | F32: 3 | H32: 2.35 | J32: =SUM(C32:I32) -> 20.76
A33: Franchises Customer App | D33: 3.5 | F33: 15.59 | J33: =SUM(C33:I33) -> 19.09
A34: Franchises myJDW | J34: =SUM(C34:I34) -> 0
A35: Franchises mySchedule | J35: =SUM(C35:I35) -> 0
A36: Franchises WordPress Websites
A37: Hotels HLS Integration | J37: =SUM(C37:I37) -> 0
A38: Hotels Price Comparison | B38: I-000317 | J38: =SUM(C38:I38) -> 0
A39: Intelligence PoC | B39: I-000318 | D39: 1 | F39: 6 | J39: =SUM(C39:I39) -> 7
A40: Microsoft Office Replacement | J40: =SUM(C40:I40) -> 0
A41: myETL
A42: myPub | B42: I-000319 | J42: =SUM(C42:I42) -> 0
A43: myDiscounts App | B43: I-000320 | D43: 13 | F43: 5.25 | H43: 3.25 | J43: =SUM(C43:I43) -> 21.5
A44: myJDW | B44: I-000239 | C44: 245.57 | D44: 171.29 | E44: 138.75 | F44: 70.66 | H44: 1 | J44: =SUM(C44:I44) -> 627.27
A45: mySchedule | B45: I-000271 | C45: 277.32 | D45: 80.89 | E45: 1.25 | F45: 117.85 | G45: 3.25 | I45: 6.02 | J45: =SUM(C45:I45) -> 486.58
A46: People Planning
...

Sheet Apr 24
A1: Month: | B1: 45383
A3: Dedicated Team Billing: | B3: =B9+B60 -> 340813
A4: Fixed Team Target Hours: | B4: =SUM(32*8.5)*22 -> 5984 | C4: 32 FTE
A5: Fixed Team Recorded Hours: | B5: =T13+J57+G72 -> 5989.93
A6: Difference: | B6: =B5-B4 -> 5.93
A9: Planning, Development & Delivery | B9: 315839
C10: R&P | D10: R&P | E10: R&P | F10: R&P | G10: R&P | H10: R&P | I10: TMC | J10: R&P | K10: TMC | L10: TMC | M10: TMC | N10: TMC | O10: TMC | P10: TMC | Q10: TMC | R10: TMC | S10: TMC
A11: Programme Management Hours | B11: Project Code | C11: Planning | D11: Project Management, Meetings & Reporting | E11: Design | F11: Admin | G11: Systems Admin | H11: Research | I11: Training | J11: Finance | K11: HR | L11: Recruitment | M11: Travel | N11: Break | O11: Lunch | P11: Holiday | Q11: Bank Holiday | R11: Sick | S11: Other Absence | T11: Total
C13: 116.27 | D13: 298.73 | E13: =SUM(E12) -> 0 | F13: 42.67 | G13: 122.34 | H13: 35.25 | I13: 71.83 | J13: 4 | K13: 21.8 | L13: 24.15 | M13: 10.75 | N13: 48.72 | O13: 436.17 | P13: 294.75 | Q13: 194.5 | R13: =SUM(R12) -> 0 | S13: 9.5 | T13: =SUM(C13:S13) -> 1731.43
A16: Projects Hours | B16: Project Code | C16: Development | D16: Project Management, Meetings & Reporting | E16: Testing | F16: Planning | G16: Systems Admin | H16: Design | I16: Release | J16: Total
A17: Allergens Service | B17: I-000300 | C17: 6.79 | D17: 25.89 | E17: 21 | G17: 0.75 | H17: 0.08 | J17: =SUM(C17:I17) -> 54.51
A18: Authentication | B18: I-000312 | D18: 7.37 | F18: 18 | J18: =SUM(C18:I18) -> 25.37
A19: Available Ales on TV Screens | J19: =SUM(C19:I19) -> 0
A20: Customer Information Screens | B20: I-000313 | C20: 1.25 | J20: =SUM(C20:I20) -> 1.25
A21: Corporate Website Replatform Build | B21: I-000300 | C21: 213.5 | D21: 24.5 | J21: =SUM(C21:I21) -> 238
A22: Customer Accounts Planning | B22: I-000311 | J22: =SUM(C22:I22) -> 0
A23: Customer App - Ibersol Franchise Integration
A24: Customer App - Lagardere Franchise Integration
A25: Customer App / PWA / App Manager | B25: I-000287 | C25: 825.01 | D25: 267.36 | E25: 562.92 | F25: 151.42 | G25: 138.79 | H25: 57.5 | I25: 5.75 | J25: =SUM(C25:I25) -> 2008.75
A26: Customer App UX/UI Redesign | J26: =SUM(C26:I26) -> 0
A27: Customer Planning
A28: Digital Pub Records | B28: I-000314 | J28: =SUM(C28:I28) -> 0
A29: Digital Vouchers | J29: =SUM(C29:I29) -> 0
A30: Disaster Recovery & Business Continuity | B30: I-000315 | J30: =SUM(C30:I30) -> 0
A31: Employee Digital Records | B31: I-000316 | D31: 31.75 | F31: 11.5 | H31: 9 | J31: =SUM(C31:I31) -> 52.25
A32: Employee Verification (with WISDOM) | B32: I-000274 | C32: 108.74 | D32: 22.31 | H32: 4 | J32: =SUM(C32:I32) -> 135.05
A33: Franchises Customer App | D33: 5 | F33: 11 | H33: 0.75 | J33: =SUM(C33:I33) -> 16.75
A34: Franchises myJDW | J34: =SUM(C34:I34) -> 0
A35: Franchises mySchedule | J35: =SUM(C35:I35) -> 0
A36: Franchises WordPress Websites
A37: Hotels HLS Integration | J37: =SUM(C37:I37) -> 0
A38: Hotels Price Comparison | B38: I-000317 | J38: =SUM(C38:I38) -> 0
A39: Intelligence PoC | B39: I-000318 | D39: 35.5 | F39: 68.67 | H39: 31.17 | J39: =SUM(C39:I39) -> 135.34
A40: Microsoft Office Replacement | J40: =SUM(C40:I40) -> 0
A41: myETL
A42: myPub | B42: I-000319 | J42: =SUM(C42:I42) -> 0
A43: myDiscounts App | B43: I-000320 | J43: =SUM(C43:I43) -> 0
A44: myJDW | B44: I-000239 | C44: 243.93 | D44: 147.94 | E44: 137.5 | F44: 83.25 | I44: 7.03 | J44: =SUM(C44:I44) -> 619.65
A45: mySchedule | B45: I-000271 | C45: 272.09 | D45: 110.15 | E45: 152.92 | F45: 108.18 | H45: 6 | I45: 3.84 | J45: =SUM(C45:I45) -> 653.18
A46: People Planning
...

Sheet May 24
A1: Month: | B1: 45413
A3: Dedicated Team Billing: | B3: =B9+B60 -> 340813
A4: Fixed Team Target Hours: | B4: =SUM(32*8.5)*23 -> 6256 | C4: 32 FTE
A5: Fixed Team Recorded Hours: | B5: =T13+J57+G72 -> 6256.39
A6: Difference: | B6: =B5-B4 -> 0.39
A9: Planning, Development & Delivery | B9: 315839
C10: R&P | D10: R&P | E10: R&P | F10: R&P | G10: R&P | H10: R&P | I10: TMC | J10: R&P | K10: TMC | L10: TMC | M10: TMC | N10: TMC | O10: TMC | P10: TMC | Q10: TMC | R10: TMC | S10: TMC
A11: Programme Management Hours | B11: Project Code | C11: Planning | D11: Project Management, Meetings & Reporting | E11: Design | F11: Admin | G11: Systems Admin | H11: Research | I11: Training | J11: Finance | K11: HR | L11: Recruitment | M11: Travel | N11: Break | O11: Lunch | P11: Holiday | Q11: Bank Holiday | R11: Sick | S11: Other Absence | T11: Total
C13: 131.92 | D13: 316.68 | E13: =SUM(E12) -> 0 | F13: 59.93 | G13: 172.92 | H13: 57.18 | I13: 141 | J13: 4.75 | K13: 35.55 | L13: 23.34 | M13: 19.5 | N13: 32.71 | O13: 439.98 | P13: 356.75 | Q13: 459 | R13: 22.68 | S13: 15 | T13: =SUM(C13:S13) -> 2288.89
A16: Projects Hours | B16: Project Code | C16: Development | D16: Project Management, Meetings & Reporting | E16: Testing | F16: Planning | G16: Systems Admin | H16: Design | I16: Release | J16: Total
A17: Allergens Service | B17: I-000300 | C17: 22.09 | D17: 10.64 | E17: 104 | F17: 0.75 | I17: 0.25 | J17: =SUM(C17:I17) -> 137.73
A18: Authentication | B18: I-000312 | D18: 32.84 | F18: 14.52 | H18: 20.5 | J18: =SUM(C18:I18) -> 67.86
A19: Available Ales on TV Screens | J19: =SUM(C19:I19) -> 0
A20: Customer Information Screens | B20: I-000313 | D20: 10.83 | F20: 35.5 | H20: 11 | J20: =SUM(C20:I20) -> 57.33
A21: Corporate Website Replatform Build | B21: I-000300 | C21: 230.25 | D21: 44 | E21: 81.25 | F21: 3.5 | H21: 10.25 | J21: =SUM(C21:I21) -> 369.25
A22: Customer Accounts Planning | B22: I-000311 | J22: =SUM(C22:I22) -> 0
A23: Customer App - Ibersol Franchise Integration
A24: Customer App - Lagardere Franchise Integration
A25: Customer App / PWA / App Manager | B25: I-000287 | C25: 777 | D25: 199.34 | E25: 184.67 | F25: 148.3 | G25: 59.92 | H25: 10.25 | I25: 11.5 | J25: =SUM(C25:I25) -> 1390.98
A26: Customer App UX/UI Redesign | J26: =SUM(C26:I26) -> 0
A27: Customer Planning
A28: Digital Pub Records | B28: I-000314 | D28: 3.07 | J28: =SUM(C28:I28) -> 3.07
A29: Digital Vouchers | J29: =SUM(C29:I29) -> 0
A30: Disaster Recovery & Business Continuity | B30: I-000315 | D30: 1 | F30: 1 | J30: =SUM(C30:I30) -> 2
A31: Employee Digital Records | B31: I-000316 | D31: 11.25 | F31: 5.75 | H31: 13.5 | J31: =SUM(C31:I31) -> 30.5
A32: Employee Verification (with WISDOM) | B32: I-000274 | C32: 15.07 | D32: 22.97 | E32: 1.42 | F32: 0.75 | I32: 1.95 | J32: =SUM(C32:I32) -> 42.16
A33: Franchises Customer App | D33: 28.17 | E33: 29.25 | F33: 76.5 | J33: =SUM(C33:I33) -> 133.92
A34: Franchises myJDW | J34: =SUM(C34:I34) -> 0
A35: Franchises mySchedule | J35: =SUM(C35:I35) -> 0
A36: Franchises WordPress Websites
A37: Hotels HLS Integration | J37: =SUM(C37:I37) -> 0
A38: Hotels Price Comparison | B38: I-000317 | D38: 3.5 | J38: =SUM(C38:I38) -> 3.5
A39: Intelligence PoC | B39: I-000318 | C39: 68.75 | D39: 48.33 | E39: 6.5 | F39: 3.75 | H39: 16.83 | I39: 5.5 | J39: =SUM(C39:I39) -> 149.66
A40: Microsoft Office Replacement | J40: =SUM(C40:I40) -> 0
A41: myETL
A42: myPub | B42: I-000319 | J42: =SUM(C42:I42) -> 0
A43: myDiscounts App | B43: I-000320 | D43: 0.5 | J43: =SUM(C43:I43) -> 0.5
A44: myJDW | B44: I-000239 | C44: 257.69 | D44: 155.8 | E44: 214 | F44: 35.55 | H44: 18.25 | I44: 0.48 | J44: =SUM(C44:I44) -> 681.77
A45: mySchedule | B45: I-000271 | C45: 281.73 | D45: 161.69 | E45: 63.25 | F45: 90.84 | G45: 9.25 | H45: 50.75 | I45: 11.67 | J45: =SUM(C45:I45) -> 669.18
A46: People Planning
...

Sheet Jun 24
A1: Month: | B1: 45444
A3: Dedicated Team Billing: | B3: =B9+B60 -> 340813
A4: Fixed Team Target Hours: | B4: =SUM(32*8.5)*20 -> 5440 | C4: 32 FTE
A5: Fixed Team Recorded Hours: | B5: =T13+J57+G72 -> 5445.86
A6: Difference: | B6: =B5-B4 -> 5.86
A9: Planning, Development & Delivery | B9: 315839
C10: R&P | D10: R&P | E10: R&P | F10: R&P | G10: R&P | H10: R&P | I10: TMC | J10: R&P | K10: TMC | L10: TMC | M10: TMC | N10: TMC | O10: TMC | P10: TMC | Q10: TMC | R10: TMC | S10: TMC
A11: Programme Management Hours | B11: Project Code | C11: Planning | D11: Project Management, Meetings & Reporting | E11: Design | F11: Admin | G11: Systems Admin | H11: Research | I11: Training | J11: Finance | K11: HR | L11: Recruitment | M11: Travel | N11: Break | O11: Lunch | P11: Holiday | Q11: Bank Holiday | R11: Sick | S11: Other Absence | T11: Total
C13: 67.25 | D13: 301.57 | E13: =SUM(E12) -> 0 | F13: 63.02 | G13: 169.78 | H13: 4.75 | I13: 86.33 | J13: 2.25 | K13: 35.75 | L13: 21.08 | M13: 12.91 | N13: 31.2 | O13: 434.48 | P13: 448 | Q13: 0 | R13: 25.5 | S13: 66.25 | T13: =SUM(C13:S13) -> 1770.12
A16: Projects Hours | B16: Project Code | C16: Development | D16: Project Management, Meetings & Reporting | E16: Testing | F16: Planning | G16: Systems Admin | H16: Design | I16: Release | J16: Total
A17: Allergens Service | B17: I-000300 | C17: 30.64 | D17: 26.61 | E17: 0.75 | G17: 1.5 | I17: 4.75 | J17: =SUM(C17:I17) -> 64.25
A18: Authentication | B18: I-000312 | C18: 91.85 | D18: 76.55 | E18: 4 | F18: 98.82 | G18: 1 | H18: 27.65 | J18: =SUM(C18:I18) -> 299.87
A19: Available Ales on TV Screens | J19: =SUM(C19:I19) -> 0
A20: Customer Information Screens | B20: I-000313 | C20: 74 | D20: 23.25 | F20: 11 | H20: 8.67 | J20: =SUM(C20:I20) -> 116.92
A21: Corporate Website Replatform Build | B21: I-000300 | C21: 323.5 | D21: 27.25 | E21: 7.5 | F21: 4 | H21: 4.5 | J21: =SUM(C21:I21) -> 366.75
A22: Customer Accounts Planning | B22: I-000311 | F22: 2 | J22: =SUM(C22:I22) -> 2
A23: Customer App - Ibersol Franchise Integration
A24: Customer App - Lagardere Franchise Integration
A25: Customer App / PWA / App Manager | B25: I-000287 | C25: 606.16 | D25: =259.88+11.5 -> 271.38 | E25: 293.2 | F25: 166.23 | G25: 120.01 | H25: 10.5 | J25: =SUM(C25:I25) -> 1467.48
A26: Customer App UX/UI Redesign | J26: =SUM(C26:I26) -> 0
A27: Customer Planning
A28: Digital Pub Records | B28: I-000314 | C28: 2.8 | D28: 9.28 | F28: 17.25 | J28: =SUM(C28:I28) -> 29.33
A29: Digital Vouchers | J29: =SUM(C29:I29) -> 0
A30: Disaster Recovery & Business Continuity | B30: I-000315 | D30: 1 | F30: 9 | J30: =SUM(C30:I30) -> 10
A31: Employee Digital Records | B31: I-000316 | D31: 34.42 | F31: 21.25 | H31: 63.75 | J31: =SUM(C31:I31) -> 119.42
A32: Employee Verification (with WISDOM) | B32: I-000274 | C32: 1.45 | D32: 11.45 | J32: =SUM(C32:I32) -> 12.9
A33: Franchises Customer App | D33: 40.09 | F33: 70.75 | G33: 9.75 | H33: 1.5 | J33: =SUM(C33:I33) -> 122.09
A34: Franchises myJDW | J34: =SUM(C34:I34) -> 0
A35: Franchises mySchedule | J35: =SUM(C35:I35) -> 0
A36: Franchises WordPress Websites
A37: Hotels HLS Integration | J37: =SUM(C37:I37) -> 0
A38: Hotels Price Comparison | B38: I-000317 | J38: =SUM(C38:I38) -> 0
A39: Intelligence PoC | B39: I-000318 | C39: 2 | D39: 9.25 | F39: 13.25 | H39: 23.25 | J39: =SUM(C39:I39) -> 47.75
A40: Microsoft Office Replacement | J40: =SUM(C40:I40) -> 0
A41: myETL
A42: myPub | B42: I-000319 | D42: 0.25 | F42: 1 | J42: =SUM(C42:I42) -> 1.25
A43: myDiscounts App | B43: I-000320 | J43: =SUM(C43:I43) -> 0
A44: myJDW | B44: I-000239 | C44: 162.13 | D44: 110.09 | E44: 1 | F44: 11 | H44: 16.25 | I44: 1.87 | J44: =SUM(C44:I44) -> 302.34
A45: mySchedule | B45: I-000271 | C45: 176.07 | D45: 112.73 | F45: 71.43 | H45: 2.5 | I45: 2 | J45: =SUM(C45:I45) -> 364.73
A46: People Planning
...

Sheet Jul 24
A1: Month: | B1: 45474
A3: Dedicated Team Billing: | B3: =B9+B60 -> 340813
A4: Fixed Team Target Hours: | B4: =SUM(32*8.5)*22 -> 5984 | C4: 32 FTE
A5: Fixed Team Recorded Hours: | B5: =T13+J57+G72 -> 6356.86
A6: Difference: | B6: =B5-B4 -> 372.86
A9: Planning, Development & Delivery | B9: 315839
C10: R&P | D10: R&P | E10: R&P | F10: R&P | G10: R&P | H10: R&P | I10: TMC | J10: R&P | K10: TMC | L10: TMC | M10: TMC | N10: TMC | O10: TMC | P10: TMC | Q10: TMC | R10: TMC | S10: TMC
A11: Programme Management Hours | B11: Project Code | C11: Planning | D11: Project Management, Meetings & Reporting | E11: Design | F11: Admin | G11: Systems Admin | H11: Research | I11: Training | J11: Finance | K11: HR | L11: Recruitment | M11: Travel | N11: Break | O11: Lunch | P11: Holiday | Q11: Bank Holiday | R11: Sick | S11: Other Absence | T11: Total
C13: 56 | D13: 414.9 | F13: 57.25 | G13: 225.97 | H13: 27 | I13: 13.62 | J13: 5 | K13: 29.5 | L13: 14.33 | M13: 17.5 | N13: 29.14 | O13: 455.34 | P13: 516 | R13: 16 | S13: 189 | T13: =SUM(C13:S13) -> 2066.55
A16: Projects Hours | B16: Project Code | C16: Development | D16: Project Management, Meetings & Reporting | E16: Testing | F16: Planning | G16: Systems Admin | H16: Design | I16: Release | J16: Total
A17: Allergens Service | B17: I-000300 | C17: 2.25 | D17: 27.42 | E17: 6.5 | G17: 2.75 | H17: 2.5 | I17: 4.28 | J17: =SUM(C17:I17) -> 45.7
A18: Authentication | B18: I-000312 | C18: 76.57 | D18: 36.67 | F18: 67.85 | H18: 32.97 | J18: =SUM(C18:I18) -> 214.06
A19: Available Ales on TV Screens | J19: =SUM(C19:I19) -> 0
A20: Customer Information Screens | B20: I-000313 | C20: 92 | D20: 23.75 | E20: 6.5 | F20: 1.25 | H20: 0.5 | J20: =SUM(C20:I20) -> 124
A21: Corporate Website Replatform Build | B21: I-000300 | C21: 107.84 | D21: 64 | E21: 160.75 | F21: 3 | H21: 2.5 | I21: 13.75 | J21: =SUM(C21:I21) -> 351.84
